<mujoco model="iiwa_workcell">
    <compiler angle="radian"/>
    <size nconmax="100" njmax="500" nstack="1270940"/>
    <option>
        <flag energy="enable"/>
    </option>
    <asset>
        <!-- Gen3 Arm Meshes -->
        <mesh name="Base_Link" file="meshes/Base_Link.stl"/>
        <mesh name="Shoulder_Link" file="meshes/Shoulder_Link.stl"/>
        <mesh name="HalfArm1_Link" file="meshes/HalfArm1_Link.stl"/>
        <mesh name="HalfArm2_Link" file="meshes/HalfArm2_Link.stl"/>
        <mesh name="ForeArm_Link" file="meshes/ForeArm_Link.stl"/>
        <mesh name="SphericalWrist1_Link" file="meshes/SphericalWrist1_Link.stl"/>
        <mesh name="SphericalWrist2_Link" file="meshes/SphericalWrist2_Link.stl"/>
        <mesh name="Bracelet_Link" file="meshes/Bracelet_Link.stl"/>
        <mesh name="Hebi_Mount_Link" file="meshes/hebi_mount.stl" scale="0.001 0.001 0.001"/>
        <mesh name="Hebi_Proximal_Link" file="meshes/hebi_proximal.stl" scale="0.001 0.001 0.001"/>
        <mesh name="Hebi_Distal_Link" file="meshes/hebi_distal.stl" scale="0.001 0.001 0.001"/>

        <material name="BeigeMaterial" specular="0" shininess="0" reflectance="0" rgba="0.26 0.16 0.16796875 1" emission="0" />
        <texture name="texplane" type="2d" builtin="checker" rgb1=".2 .3 .4" rgb2=".1 0.15 0.2" width="512" height="512" />
        <material name="MatPlane" reflectance="0" texture="texplane" texrepeat="1 1" texuniform="true" />
        <material name="MatGnd" specular=".3" shininess=".3" reflectance="0.3" rgba=".5 .55 .5 1"/>
    </asset>

    <worldbody>
        <!-- Lights -->
        <light name="light0" diffuse=".5 .5 .5" pos="1.5 1.5 2"   dir="-1 -1 -.5" castshadow="false" />
        <light name="light1" diffuse=".5 .5 .5" pos="-1.5 1.5 2"  dir="1 -1 -.5" castshadow="false" />
        <light name="light2" diffuse=".5 .5 .5" pos="1.5 -1.5 2"  dir="-1 1 -.5" castshadow="false" />
        <light name="light3" diffuse=".5 .5 .5" pos="-1.5 -1.5 2" dir="1 1 -.5" castshadow="false" />
        <!-- Floor -->
        <geom name="floor" pos="0 0 0" size="5 5 .125" type="plane" material="MatPlane" condim="3"  contype="1" conaffinity="1"/>
        <!-- <geom name="tplane" pos="0.3 0 0.77153" quat="0.707 0 0 0.707" type="plane" size="0.4 0.625 1e-3" group = "1" rgba="0 0 0 0" /> -->
        <!-- Environment: Workcell -->
        <body name="workcell" pos="0 0 0" quat="0.707 0 0 -0.707">
            <geom name="table" size="0.3 0.625 0.385765" pos="0 0.3 0.385765" type="box" rgba="0.16 0.24 0.32 1"  conaffinity="32" contype="32"/>
            <!-- <geom name="table" size="0.9144 0.4572 0.385765" pos="0 0 0.385765" type="box" rgba="0.16 0.24 0.32 1"  conaffinity="32" contype="32" condim='1' friction='0.99 0.99 0.99' priority="1"/> -->
        </body>



        <!--  ================= box left ================= /-->
        <body name="box_left" pos="2 1.4 0" euler="0 0 1.57" >
            <geom name="t1" material="MatGnd" type="box" pos="0.5 0.9 0.9" size="1.5 0.3 0.05" rgba=".6 .6 .5 0.4" conaffinity="32" contype="32" condim='1' priority="1"/>
            <geom name="t2" material="MatGnd" type="box" pos="0.5 0.9 1.3" size="1.5 0.3 0.05" rgba=".6 .6 .5 0.4" conaffinity="32" contype="32" friction='0.99 0.99 0.99'  priority="1"/>
            <geom name="t3" material="MatGnd" type="box" pos="0.5 0.6 1.1" size="0.2 1.5 0.05" euler="1.5707 0 1.5707" rgba=".6 .6 .5 0.4" conaffinity="32" contype="32" friction='0.99 0.99 0.99'  priority="1"/>
            <geom name="t4" material="MatGnd" type="box" pos="0.5 1.2 1.1" size="0.2 1.5 0.05" euler="1.5707 0 1.5707" rgba=".6 .6 .5 0.4" conaffinity="32" contype="32" friction='0.99 0.99 0.99'  priority="1"/>
        </body>

        <!-- Robot: gen3 -->
        <body name="Base_Link"  pos="0.8 -0.0381 0.78106" quat="0.707 0 0 -0.707">
             <!-- table slide --> 
        <!-- <body name="Base_Link"  pos="0.4064 -0.508 0.77153" quat="0 0 0 1"> -->
        <!-- <body name="Base_Link"  pos="0 0 0.78106" quat="0.707 0 0 -0.707"> -->
            <inertial pos="-0.000648 -0.000166 0.084487" mass="1.697353" fullinertia="0.004622 0.004495 0.002079 -9E-06 -6E-05 -9E-06"/>
            <geom type="mesh" rgba="0.79216 0.81961 0.93333 1" mesh="Base_Link" conaffinity="32" contype="32"/>

            <body name="Shoulder_Link" pos="6.1995e-05 0 0.17" quat="-3.67321e-06 -1 0 0">
                <!-- <inertial pos="-2.3e-05 -0.010364 -0.07336" quat="0.707051 0.0451246 -0.0453544 0.704263" mass="1.37735" fullinertia="0.00457 0.004831 0.001409 -1E-06 -2E-06 -0.000448"/> -->
                <inertial pos="-2.3e-05 -0.010364 -0.07336" mass="1.37735" fullinertia="0.00457 0.004831 0.001409 -1E-06 -2E-06 -0.000448"/>
                <joint name="Actuator1" pos="0 0 0" axis="0 0 1"/>
                <geom type="mesh" rgba="0.75294 0.75294 0.75294 1" mesh="Shoulder_Link" conaffinity="32" contype="32"/>

                <body name="HalfArm1_Link" pos="0 0.005375 -0.12838" quat="0.707105 0.707108 0 0">
                    <inertial pos="-4.4e-05 -0.09958 -0.013278" quat="0.482348 0.516286 -0.516862 0.483366" mass="1.16367" diaginertia="0.0113017 0.011088 0.00102532"/>
                    <!-- <joint name="Actuator2" pos="0 0 0" axis="0 0 1" limited="true" range="-2.2 2.2"/> -->
                    <joint name="Actuator2" pos="0 0 0" axis="0 0 1"/>
                    <geom type="mesh" rgba="0.75294 0.75294 0.75294 1" mesh="HalfArm1_Link" conaffinity="32" contype="32"/>

                    <body name="HalfArm2_Link" pos="0 -0.21038 -0.006375" quat="0.707105 -0.707108 0 0">
                        <inertial pos="-4.4e-05 -0.006641 -0.117892" quat="0.706144 0.0213722 -0.0209128 0.707437" mass="1.16366" diaginertia="0.0111633 0.010932 0.00100671"/>
                        <joint name="Actuator3" pos="0 0 0" axis="0 0 1"/>
                        <geom type="mesh" rgba="0.75294 0.75294 0.75294 1" mesh="HalfArm2_Link" conaffinity="32" contype="32"/>

                        <body name="ForeArm_Link" pos="0 0.006375 -0.21038" quat="0.707105 0.707108 0 0">
                            <inertial pos="-1.8e-05 -0.075478 -0.015006" quat="0.483678 0.515961 -0.515859 0.483455" mass="0.930287" diaginertia="0.00834839 0.008147 0.000598606"/>
                            <joint name="Actuator4" pos="0 0 0" axis="0 0 1" limited="true" range="-2.5656 2.5656"/>
                            <geom type="mesh" rgba="0.75294 0.75294 0.75294 1" mesh="ForeArm_Link" conaffinity="32" contype="32"/>
                            <site name="ForeArm_Link" type="sphere" size="1e-3" pos="0 0 6e-3" group="2" rgba="0 1 0 1" />

                            <body name="SphericalWrist1_Link" pos="0 -0.20843 -0.006375" quat="0.707105 -0.707108 0 0">
                                <inertial pos="1e-06 -0.009432 -0.063883" quat="0.703558 0.0707492 -0.0707492 0.703558" mass="0.678106" diaginertia="0.00165901 0.001596 0.000346988"/>
                                <joint name="Actuator5" pos="0 0 0" axis="0 0 1"/>
                                <geom type="mesh" rgba="0.75294 0.75294 0.75294 1" mesh="SphericalWrist1_Link" conaffinity="32" contype="32"/>
                                <site name="SphericalWrist1_Link" type="sphere" size="1e-3" pos="0 0 6e-3" group="2" rgba="0 1 0 1" />

                                <body name="SphericalWrist2_Link" pos="0 0.00017505 -0.10593" quat="0.707105 0.707108 0 0">
                                    <inertial pos="1e-06 -0.045483 -0.00965" quat="0.44426 0.550121 -0.550121 0.44426" mass="0.678106" diaginertia="0.00170087 0.001641 0.00035013"/>
                                    <!-- <joint name="Actuator6" pos="0 0 0" axis="0 0 1" limited="true" range="-2.05 2.05"/> -->
                                    <joint name="Actuator6" pos="0 0 0" axis="0 0 1"/>
                                    <geom type="mesh" rgba="0.75294 0.75294 0.75294 1" mesh="SphericalWrist2_Link" conaffinity="32" contype="32"/>
                                    <site name="SphericalWrist2_Link" type="sphere" size="1e-3" pos="0 0 6e-3" group="2" rgba="0 1 0 1" />

                                    <body name="Bracelet_Link" pos="0 -0.10593 -0.00017505" quat="0.707105 -0.707108 0 0">
                                        <inertial pos="-0.000281 -0.011402 -0.03108" quat="0.592556 0.413116 -0.393675 0.568536" mass="0.500657" diaginertia="0.000650457 0.00056985 0.000310694"/>
                                        <joint name="Actuator7" pos="0 0 0" axis="0 0 1"/>
                                        <geom type="mesh" rgba="0.75294 0.75294 0.75294 1" mesh="Bracelet_Link" conaffinity="32" contype="32"/>
                                        <site name="Bracelet_Link" type="sphere" size="1e-3" pos="0 0 6e-3" group="2" rgba="0 1 0 1" />

                                        <!-- <body name="Hebi_Mount_Link" pos="0 0 -0.064" quat="0.0 1.0 0.0 0.0"> -->
                                        <body name="Hebi_Mount_Link" pos="0 0 -0.064" quat="0.0 0.707107 -0.707107 0.0 ">
                                            <inertial pos="-0.00687 -0.006559 0.0467" mass="0.9194" fullinertia="0.00134 0.00124 0.000921 0.00006684 0.0000428 0.0001143"/>
                                            <geom type="mesh" rgba="0.75294 0.75294 0.75294 1" mesh="Hebi_Mount_Link" conaffinity="32" contype="32"/>
                                            <site name="Hebi_Mount_Link" type="sphere" size="1e-3" pos="0 0 6e-3" group="2" rgba="0 1 0 1" />

                                            <body name="Hebi_Proximal_Link" pos="0.02255 0 0.0683" quat="0.0 0.707107 0.0 0.707107">
                                                <inertial pos="0.02088 0.01 -0.0675" mass="0.79" fullinertia="0.00058 0.00787 0.00777 -0.0000112 0.000768 0.0000114"/>
                                                <joint name="Actuator8" pos="0 0 0" axis="0 0 1"/>
                                                <geom type="mesh" rgba="0.75294 0.75294 0.75294 1" mesh="Hebi_Proximal_Link" conaffinity="32" contype="32"/>
                                                <site name="Hebi_Proximal_Link" type="sphere" size="1e-3" pos="0 0 6e-3" group="2" rgba="0 1 0 1" />

                                                <body name="Hebi_Distal_Link" pos="0.2755 0 -0.04505" quat="0.0 1.0 0.0 0.0">
                                                    <inertial pos="0.0675 0.0000038 0.01412" mass="0.2144" fullinertia="0.000076 0.00135 0.00136 0.0 -0.000086 0.0"/>
                                                    <joint name="Actuator9" pos="0 0 0" axis="0 0 1"/>
                                                    <geom type="mesh" rgba="0.75294 0.75294 0.75294 1" mesh="Hebi_Distal_Link" conaffinity="32" contype="32"/>
                                                    <site name="Hebi_Distal_Link" type="sphere" size="1e-3" pos="0 0 6e-3" group="2" rgba="0 1 0 1" />
                                                </body>
                                            </body>
                                        </body>


<!--                                         <body name="ee_link" pos="0 0 -0.064" quat="0.707105 -0.707108 0 0">
                                            <inertial pos="-0.01 0 0" mass="0.001"  diaginertia="1.66667e-08 1.66667e-08 1.66667e-08" />
                                            <geom size="0.005 0.005 0.005" friction="0.8 0.8 0.8" pos="-0.01 0 0" type="box" />
                                            <site name="ee_link" type="sphere" size="1e-3" pos="0 0 6e-3" group="2" rgba="0 1 0 1" />

                                            <body name="object" pos="0 0 0" quat="1 0 0 0" >
                                                <inertial pos="0 0 0" mass=".155" diaginertia="0.0003686049833333333 0.001255996129167 0.001460916979167" />
                                                <geom name="object" type="sphere" size="0.04" group="1" rgba=".9 0 0 1"  contype="1" conaffinity="1"/>            
                                            </body>
                                        </body> -->

                                    </body>
                                </body>
                            </body>
                        </body>
                    </body>
                </body>
            </body>
        </body>
    </worldbody>

    <!-- Actuators -->
    <actuator>
        <motor name="Shoulder_Link_motor" joint="Actuator1" ctrlrange="-39 39" ctrllimited="true"/>
        <motor name="HalfArm1_Link_motor" joint="Actuator2" ctrlrange="-39 39" ctrllimited="true"/>
        <motor name="HalfArm2_Link_motor" joint="Actuator3" ctrlrange="-39 39" ctrllimited="true"/>
        <motor name="ForeArm_Link_motor" joint="Actuator4" ctrlrange="-39 39" ctrllimited="true"/>
        <motor name="SphericalWrist1_Link_motor" joint="Actuator5" ctrlrange="-9 9" ctrllimited="true"/>
        <motor name="SphericalWrist2_Link_motor" joint="Actuator6" ctrlrange="-9 9" ctrllimited="true"/>
        <motor name="Bracelet_Link_motor" joint="Actuator7" ctrlrange="-9 9" ctrllimited="true"/>
        <motor name="Hebi_Proximal_motor" joint="Actuator8" ctrlrange="-9 9" ctrllimited="true"/>
        <motor name="Hebi_Distal_motor" joint="Actuator9" ctrlrange="-9 9" ctrllimited="true"/>
    </actuator>

    <!-- Key frames -->
    <keyframe>
    </keyframe>

</mujoco>