<mujoco model="iiwa_workcell">
    <compiler angle="radian"/>
    <size nconmax="100" njmax="500" nstack="1270940"/>
    <option>
        <flag energy="enable"/>
    </option>
    <asset>
        <!-- Gen3 Arm Meshes -->
        <mesh name="Base_Link" file="meshes/Base_Link.stl"/>
        <mesh name="Shoulder_Link" file="meshes/Shoulder_Link.stl"/>
        <mesh name="HalfArm1_Link" file="meshes/HalfArm1_Link.stl"/>
        <mesh name="HalfArm2_Link" file="meshes/HalfArm2_Link.stl"/>
        <mesh name="ForeArm_Link" file="meshes/ForeArm_Link.stl"/>
        <mesh name="SphericalWrist1_Link" file="meshes/SphericalWrist1_Link.stl"/>
        <mesh name="SphericalWrist2_Link" file="meshes/SphericalWrist2_Link.stl"/>
        <mesh name="Bracelet_Link" file="meshes/Bracelet_Link.stl"/>
        <mesh name="Hebi_Mount_Link" file="meshes/hebi_mount.stl"/>
        <mesh name="Hebi_Proximal_Link" file="meshes/hebi_proximal.stl"/>
        <mesh name="Hebi_Distal_Link" file="meshes/hebi_distal.stl"/>
        <!-- Robotiq Hand Meshes -->
<!--         <mesh name="robotiq_85_base_link_coarse" file="robotiq/robotiq_85_base_link_coarse.stl"/>
        <mesh name="outer_knuckle_coarse" file="robotiq/outer_knuckle_coarse.stl"/>
        <mesh name="outer_finger_coarse" file="robotiq/outer_finger_coarse.stl"/>
        <mesh name="inner_knuckle_coarse" file="robotiq/inner_knuckle_coarse.stl"/>
        <mesh name="inner_finger_coarse" file="robotiq/inner_finger_coarse.stl"/> -->

        <material name="BeigeMaterial" specular="0" shininess="0" reflectance="0" rgba="0.26 0.16 0.16796875 1" emission="0" />
        <texture name="texplane" type="2d" builtin="checker" rgb1=".2 .3 .4" rgb2=".1 0.15 0.2" width="512" height="512" />
        <material name="MatPlane" reflectance="0" texture="texplane" texrepeat="1 1" texuniform="true" />
        <material name="MatGnd" specular=".3" shininess=".3" reflectance="0.3" rgba=".5 .55 .5 1"/>
    </asset>

    <worldbody>
        <!-- Lights -->
        <light name="light0" diffuse=".5 .5 .5" pos="1.5 1.5 2"   dir="-1 -1 -.5" castshadow="false" />
        <light name="light1" diffuse=".5 .5 .5" pos="-1.5 1.5 2"  dir="1 -1 -.5" castshadow="false" />
        <light name="light2" diffuse=".5 .5 .5" pos="1.5 -1.5 2"  dir="-1 1 -.5" castshadow="false" />
        <light name="light3" diffuse=".5 .5 .5" pos="-1.5 -1.5 2" dir="1 1 -.5" castshadow="false" />
        <!-- Floor -->
        <geom name="floor" pos="0 0 0" size="5 5 .125" type="plane" material="MatPlane" condim="3"  contype="1" conaffinity="1"/>
        <!-- <geom name="tplane" pos="0.3 0 0.77153" quat="0.707 0 0 0.707" type="plane" size="0.4 0.625 1e-3" group = "1" rgba="0 0 0 0" /> -->
        <!-- Environment: Workcell -->
        <body name="workcell" pos="0 0 0" quat="0.707 0 0 -0.707">
            <geom name="table" size="0.3 0.625 0.385765" pos="0 0.3 0.385765" type="box" rgba="0.16 0.24 0.32 1"  conaffinity="32" contype="32"/>
            <!-- <geom name="table" size="0.9144 0.4572 0.385765" pos="0 0 0.385765" type="box" rgba="0.16 0.24 0.32 1"  conaffinity="32" contype="32" condim='1' friction='0.99 0.99 0.99' priority="1"/> -->
        </body>


        <!--  ================= Confined ================= /-->
        <!-- oblique -->
        <!-- <body name="confined" pos="-2.6 0.4 0.8" quat="1 0 0 0" > -->
        <!-- straight -->
            <!-- <geom name="t1" material="MatGnd" type="box" pos="5.2 0 0.4" size="1.5 0.3 0.05" rgba=".6 .6 .5 0.4" conaffinity="32" contype="32" friction='0.99 0.99 0.99' priority="1"/> -->
<!--         <body name="confined" pos="-2.6 0 0.9" quat="1 0 0 0" >
            <geom name="t1" material="MatGnd" type="box" pos="5.2 0 0.4" size="1.5 0.3 0.05" rgba=".6 .6 .5 0.4" conaffinity="32" contype="32" condim='1' priority="1"/>
            <geom name="t2" material="MatGnd" type="box" pos="5.2 0 0.8" size="1.5 0.3 0.05" rgba=".6 .6 .5 0.4" conaffinity="32" contype="32" friction='0.99 0.99 0.99'  priority="1"/>
            <geom name="t3" material="MatGnd" type="box" pos="5.2 -0.3 0.6" size="0.2 1.5 0.05" euler="1.5707 0 1.5707" rgba=".6 .6 .5 0.4" conaffinity="32" contype="32" friction='0.99 0.99 0.99'  priority="1"/>
            <geom name="t4" material="MatGnd" type="box" pos="5.2 0.3 0.6" size="0.2 1.5 0.05" euler="1.5707 0 1.5707" rgba=".6 .6 .5 0.4" conaffinity="32" contype="32" friction='0.99 0.99 0.99'  priority="1"/>
        </body> -->

        <!--  ================= table ================= /-->
<!--         <body name="table" pos="-2.6 0 0.9" quat="1 0 0 0" >
            <geom name="t1" material="MatGnd" type="box" pos="5.2 0 0.4" size="1.5 1.5 0.05" rgba=".6 .6 .5 0.4" conaffinity="32" contype="32" friction='0.99 0.99 0.99'  priority="1"/>
            <site name="table_top" pos="5.2 0 0.45" quat="1 0 0 0" type="box" size="1e-5 0.04 0.02" group="2" rgba="1 1 0 1" />
        </body>
 -->

        <!--  ================= box left ================= /-->
            <!-- <geom name="t1" material="MatGnd" type="box" pos="5.2 0 0.4" size="1.5 0.3 0.05" rgba=".6 .6 .5 0.4" conaffinity="32" contype="32" friction='0.99 0.99 0.99' priority="1"/> -->
        <body name="box_left" pos="2 1.4 0" euler="0 0 1.57" >
            <geom name="t1" material="MatGnd" type="box" pos="0.5 0.9 0.9" size="1.5 0.3 0.05" rgba=".6 .6 .5 0.4" conaffinity="32" contype="32" condim='1' priority="1"/>
            <geom name="t2" material="MatGnd" type="box" pos="0.5 0.9 1.3" size="1.5 0.3 0.05" rgba=".6 .6 .5 0.4" conaffinity="32" contype="32" friction='0.99 0.99 0.99'  priority="1"/>
            <geom name="t3" material="MatGnd" type="box" pos="0.5 0.6 1.1" size="0.2 1.5 0.05" euler="1.5707 0 1.5707" rgba=".6 .6 .5 0.4" conaffinity="32" contype="32" friction='0.99 0.99 0.99'  priority="1"/>
            <geom name="t4" material="MatGnd" type="box" pos="0.5 1.2 1.1" size="0.2 1.5 0.05" euler="1.5707 0 1.5707" rgba=".6 .6 .5 0.4" conaffinity="32" contype="32" friction='0.99 0.99 0.99'  priority="1"/>
        </body>

        <!--  ================= table left ================= /-->
            <!-- <geom name="tl" material="MatGnd" type="box" pos="0.5 0.9 0.9" size="1.5 0.6 0.05" rgba=".6 .6 .5 0.4" conaffinity="32" contype="32" priority="1"/> -->
<!--         <body name="table_left" pos="0 0 0" euler="0 0 0" >
            <geom name="tl" material="MatGnd" type="box" pos="0.5 0.9 0.9" size="1.5 0.6 0.05" rgba=".6 .6 .5 0.4" conaffinity="32" contype="32" condim='1' priority="1"/>
            <site name="tlsite" pos="5.2 0 0.45" quat="1 0 0 0" type="box" size="1e-5 0.04 0.02" group="2" rgba="1 1 0 1" />
        </body> -->

        <!--  ================= table right ================= /-->
            <!-- <geom name="tr" material="MatGnd" type="box" pos="-0.1 -0.9 0.9" size="1 0.6 0.05" rgba=".6 .6 .5 0.4" conaffinity="32" contype="32" priority="1"/> -->
        <body name="table_right" pos="0 0 0" euler="0 0 0" >
            <geom name="tr" material="MatGnd" type="box" pos="-0.1 -0.9 0.9" size="1 0.6 0.05" rgba=".6 .6 .5 0.4" conaffinity="32" contype="32" condim='1' priority="1"/>
            <site name="trsite" pos="5.2 0 0.45" quat="1 0 0 0" type="box" size="1e-5 0.04 0.02" group="2" rgba="1 1 0 1" />
        </body>


        <!-- Robot: gen3 -->
        <body name="Base_Link"  pos="0.8 -0.0381 0.78106" quat="0.707 0 0 -0.707">
             <!-- table slide --> 
        <!-- <body name="Base_Link"  pos="0.4064 -0.508 0.77153" quat="0 0 0 1"> -->
        <!-- <body name="Base_Link"  pos="0 0 0.78106" quat="0.707 0 0 -0.707"> -->
            <inertial pos="-0.000648 -0.000166 0.084487" mass="1.697353" fullinertia="0.004622 0.004495 0.002079 -9E-06 -6E-05 -9E-06"/>
            <geom type="mesh" rgba="0.79216 0.81961 0.93333 1" mesh="Base_Link" conaffinity="32" contype="32"/>

            <body name="Shoulder_Link" pos="6.1995e-05 0 0.17" quat="-3.67321e-06 -1 0 0">
                <!-- <inertial pos="-2.3e-05 -0.010364 -0.07336" quat="0.707051 0.0451246 -0.0453544 0.704263" mass="1.37735" fullinertia="0.00457 0.004831 0.001409 -1E-06 -2E-06 -0.000448"/> -->
                <inertial pos="-2.3e-05 -0.010364 -0.07336" mass="1.37735" fullinertia="0.00457 0.004831 0.001409 -1E-06 -2E-06 -0.000448"/>
                <joint name="Actuator1" pos="0 0 0" axis="0 0 1"/>
                <geom type="mesh" rgba="0.75294 0.75294 0.75294 1" mesh="Shoulder_Link" conaffinity="32" contype="32"/>

                <body name="HalfArm1_Link" pos="0 0.005375 -0.12838" quat="0.707105 0.707108 0 0">
                    <inertial pos="-4.4e-05 -0.09958 -0.013278" quat="0.482348 0.516286 -0.516862 0.483366" mass="1.16367" diaginertia="0.0113017 0.011088 0.00102532"/>
                    <!-- <joint name="Actuator2" pos="0 0 0" axis="0 0 1" limited="true" range="-2.2 2.2"/> -->
                    <joint name="Actuator2" pos="0 0 0" axis="0 0 1"/>
                    <geom type="mesh" rgba="0.75294 0.75294 0.75294 1" mesh="HalfArm1_Link" conaffinity="32" contype="32"/>

                    <body name="HalfArm2_Link" pos="0 -0.21038 -0.006375" quat="0.707105 -0.707108 0 0">
                        <inertial pos="-4.4e-05 -0.006641 -0.117892" quat="0.706144 0.0213722 -0.0209128 0.707437" mass="1.16366" diaginertia="0.0111633 0.010932 0.00100671"/>
                        <joint name="Actuator3" pos="0 0 0" axis="0 0 1"/>
                        <geom type="mesh" rgba="0.75294 0.75294 0.75294 1" mesh="HalfArm2_Link" conaffinity="32" contype="32"/>

                        <body name="ForeArm_Link" pos="0 0.006375 -0.21038" quat="0.707105 0.707108 0 0">
                            <inertial pos="-1.8e-05 -0.075478 -0.015006" quat="0.483678 0.515961 -0.515859 0.483455" mass="0.930287" diaginertia="0.00834839 0.008147 0.000598606"/>
                            <joint name="Actuator4" pos="0 0 0" axis="0 0 1" limited="true" range="-2.5656 2.5656"/>
                            <geom type="mesh" rgba="0.75294 0.75294 0.75294 1" mesh="ForeArm_Link" conaffinity="32" contype="32"/>
                            <site name="ForeArm_Link" type="sphere" size="1e-3" pos="0 0 6e-3" group="2" rgba="0 1 0 1" />

                            <body name="SphericalWrist1_Link" pos="0 -0.20843 -0.006375" quat="0.707105 -0.707108 0 0">
                                <inertial pos="1e-06 -0.009432 -0.063883" quat="0.703558 0.0707492 -0.0707492 0.703558" mass="0.678106" diaginertia="0.00165901 0.001596 0.000346988"/>
                                <joint name="Actuator5" pos="0 0 0" axis="0 0 1"/>
                                <geom type="mesh" rgba="0.75294 0.75294 0.75294 1" mesh="SphericalWrist1_Link" conaffinity="32" contype="32"/>
                                <site name="SphericalWrist1_Link" type="sphere" size="1e-3" pos="0 0 6e-3" group="2" rgba="0 1 0 1" />

                                <body name="SphericalWrist2_Link" pos="0 0.00017505 -0.10593" quat="0.707105 0.707108 0 0">
                                    <inertial pos="1e-06 -0.045483 -0.00965" quat="0.44426 0.550121 -0.550121 0.44426" mass="0.678106" diaginertia="0.00170087 0.001641 0.00035013"/>
                                    <!-- <joint name="Actuator6" pos="0 0 0" axis="0 0 1" limited="true" range="-2.05 2.05"/> -->
                                    <joint name="Actuator6" pos="0 0 0" axis="0 0 1"/>
                                    <geom type="mesh" rgba="0.75294 0.75294 0.75294 1" mesh="SphericalWrist2_Link" conaffinity="32" contype="32"/>
                                    <site name="SphericalWrist2_Link" type="sphere" size="1e-3" pos="0 0 6e-3" group="2" rgba="0 1 0 1" />

                                    <body name="Bracelet_Link" pos="0 -0.10593 -0.00017505" quat="0.707105 -0.707108 0 0">
                                        <inertial pos="-0.000281 -0.011402 -0.03108" quat="0.592556 0.413116 -0.393675 0.568536" mass="0.500657" diaginertia="0.000650457 0.00056985 0.000310694"/>
                                        <joint name="Actuator7" pos="0 0 0" axis="0 0 1"/>
                                        <geom type="mesh" rgba="0.75294 0.75294 0.75294 1" mesh="Bracelet_Link" conaffinity="32" contype="32"/>
                                        <site name="Bracelet_Link" type="sphere" size="1e-3" pos="0 0 6e-3" group="2" rgba="0 1 0 1" />

                                        <body name="ee_link" pos="0 0 -0.064" quat="0.707105 -0.707108 0 0">
                                            <inertial pos="-0.01 0 0" mass="0.001"  diaginertia="1.66667e-08 1.66667e-08 1.66667e-08" />
                                            <geom size="0.005 0.005 0.005" friction="0.8 0.8 0.8" pos="-0.01 0 0" type="box" />
                                            <site name="ee_link" type="sphere" size="1e-3" pos="0 0 6e-3" group="2" rgba="0 1 0 1" />

                                            <body name="object" pos="0 0 0" quat="1 0 0 0" >
                                                <inertial pos="0 0 0" mass=".155" diaginertia="0.0003686049833333333 0.001255996129167 0.001460916979167" />
                                                <geom name="object" type="sphere" size="0.04" group="1" rgba=".9 0 0 1"  contype="1" conaffinity="1"/>            
                                            </body>
                                        </body>

                                        <!-- Robotiq Gripper Links -->
    <!--                                     <body name="ee_link" pos="0 0 -0.064" quat="0.707105 -0.707108 0 0">
                                            <inertial pos="-0.01 0 0" mass="0.001"  diaginertia="1.66667e-08 1.66667e-08 1.66667e-08" />
                                            <geom size="0.005 0.005 0.005" friction="0.8 0.8 0.8" pos="-0.01 0 0" type="box" />

                                            <body name="robotiq_85_base_link" pos="0 0 0" quat="0.707105 -0.707108 0 0">
                                                <inertial pos="0.00021987 -2.3546e-10 0.030163"  quat="0.707058 0.00723369 0.00723345 0.707081" mass="0.30915" diaginertia="0.00030737 0.000289758 0.000199102" />
                                                <geom type="mesh" rgba="0.1 0.1 0.1 1" friction="0.8 0.8 0.8" mesh="robotiq_85_base_link_coarse" />

                                                <body name="left_outer_knuckle" pos="0.0306011 0 0.062792">
                                                    <inertial pos="0.0178332 3.68915e-11 0.00214425"  quat="0.463241 0.534235 0.534235 0.463241" mass="0.00684839" diaginertia="1.38892e-06 1.28691e-06 2.45951e-07" />
                                                    <geom type="mesh" rgba="0.1 0.1 0.1 1" friction="0.2 0. 0.4" mesh="outer_knuckle_coarse" />
                                                    <body name="left_outer_finger" pos="0.031691 0 -0.00193396">
                                                        <inertial pos="0.00131452 0 0.0215404"  quat="0.999536 0 -0.0304703 0" mass="0.0273094" diaginertia="8.53972e-06 6.91333e-06 2.22664e-06" />
                                                        <geom type="mesh" rgba="0.1 0.1 0.1 1" friction="0.8 0.8 0.8" mesh="outer_finger_coarse" />
                                                    </body>
                                                </body>

                                                <body name="left_inner_knuckle" pos="0.0127 0 0.0693075">
                                                    <inertial pos="0.0170975 -3.93809e-10 0.0224918"   quat="0.947655 0 -0.319297 0" mass="0.0110931" diaginertia="5.59353e-06 3.96549e-06 1.88108e-06" />
                                                    <geom type="mesh" rgba="0.1 0.1 0.1 1" friction="0.8 0.8 0.8" mesh="inner_knuckle_coarse" />

                                                    <body name="left_inner_finger" pos="0.0345853 0 0.045497" >
                                                        <inertial pos="0.00602756 0 0.00669926"  quat="0.699065 0.106339 0.106339 0.699065" mass="0.00724255" diaginertia="1.70064e-06 1.58577e-06 3.69621e-07" />
                                                        <geom type="mesh" rgba="0.1 0.1 0.1 1" friction="0.8 0.8 0.8" mesh="inner_finger_coarse" />
                                                        <joint axis="1 0 0" name="left_inner_finger_joint" range="0 0.05" type="slide"></joint>
                                                    </body>
                                                </body>

                                                <body name="right_inner_knuckle" pos="-0.0127 0 0.0693075" quat="0 0 0 1">
                                                    <inertial pos="0.0168606 3.93808e-10 0.02267"  quat="0.949317 0 -0.314322 0" mass="￼0.0110931" diaginertia="5.59353e-06 3.96549e-06 1.88108e-06" />
                                                    <geom type="mesh" rgba="0.1 0.1 0.1 1" friction="0.8 0.8 0.8" mesh="inner_knuckle_coarse" />
                                                    <body name="right_inner_finger" pos="0.034106 0 0.0458574">
                                                        <inertial pos="0.00602756 0 0.00669926"  quat="0.699065 0.106339 0.106339 0.699065" mass="0.00724255" diaginertia="1.70064e-06 1.58577e-06 3.69621e-07" />
                                                        <geom type="mesh" rgba="0.1 0.1 0.1 1" friction="0.8 0.8 0.8" mesh="inner_finger_coarse" />
                                                        <joint axis="-1 0 0" name="right_inner_finger_joint" range="0 0.05" type="slide"></joint>
                                                    </body>
                                                </body>

                                                <body name="right_outer_knuckle" pos="-0.0306011 0 0.062792" quat="0 0 0 1">
                                                    <inertial pos="0.0178097 3.60493e-11 0.00233123"  quat="0.460432 0.536658 0.536658 0.460432" mass="0.00684839" diaginertia="1.38892e-06 1.28691e-06 2.45951e-07" />
                                                    <geom type="mesh" rgba="0.1 0.1 0.1 1" friction="0.8 0.8 0.8" mesh="outer_knuckle_coarse" />
                                                    <body name="right_outer_finger" pos="0.0317096 0 -0.00160136">
                                                        <inertial pos="0.00108844 0 0.021553"  quat="0.999682 0 -0.0252262 0" mass="0.0273094" diaginertia="8.53972e-06 6.91333e-06 2.22664e-06" />
                                                        <geom type="mesh" rgba="0.1 0.1 0.1 1" friction="0.8 0.8 0.8" mesh="outer_finger_coarse" />
                                                    </body>
                                                </body>
                                            </body>
                                        </body>
     -->                                    
                                    </body>
                                </body>
                            </body>
                        </body>
                    </body>
                </body>
            </body>
        </body>
        <!-- Ghost representing the desired pose -->
<!--         <body name="ghost" pos="0 0 0" >
            <geom name="ghost" pos="0 0 0" type="box" size="0.15075 0.0745 0.038" group="0" rgba="0 .9 0 0.3" />
        </body> -->

        <!-- Object: Red ball -->
<!--         <body name="object" pos="1.65 -0.075 1.385" quat="1 0 0 0" >
            <inertial pos="0 0 0" mass=".155" diaginertia="0.0003686049833333333 0.001255996129167 0.001460916979167" />
            <joint name="object" type="free" limited="false" />
            <geom name="object" type="sphere" size="0.04" group="1" rgba=".9 0 0 1"  contype="1" conaffinity="1"/>            
        </body> -->
        <!-- Object: Red cardboard -->
<!--         <body name="object" pos="1.65 -0.075 1.385" quat="1 0 0 0" >
            <site name="obj_front" pos="-0.15074 0 0" quat="1 0 0 0"          type="box" size="1e-5 0.04 0.02" group="2" rgba="1 1 0 .1" />
            <site name="obj_right" pos="0 -0.07449 0" quat="0.707 0 0 0.707"  type="box" size="1e-5 0.10 0.02" group="2" rgba="1 1 0 .1" />
            <site name="obj_left"  pos="0 +0.07449 0" quat="0.707 0 0 -0.707" type="box" size="1e-5 0.10 0.02" group="2" rgba="1 1 0 .1" />
            <site name="obj_rear"  pos="+0.15074 0 0" quat="0 0 0 1"          type="box" size="1e-5 0.04 0.02" group="2" rgba="1 1 0 .1" />
        </body> -->
        <!-- Object: imaginary blue cube -->
        <!-- <body name="object" pos="0.5 0 0.875" quat="1 0 0 0" >
            <inertial pos="0 0 0" mass="2." diaginertia="0.00750000000 0.00750000000 0.00750000000" />
            <joint name="object" type="free" limited="false" />
            <geom name="object" type="box" size="0.075 0.075 0.075" group="1" rgba="0 0 .8 1" />
            <site name="obj_front" pos="-0.075 0 0" quat="1 0 0 0"          type="box" size="1e-5 0.02 0.02" group="2" rgba="0 1 0 .1" />
            <site name="obj_right" pos="0 -0.075 0" quat="0.707 0 0 0.707"  type="box" size="1e-5 0.02 0.02" group="2" rgba="0 1 0 .1" />
            <site name="obj_left"  pos="0 +0.075 0" quat="0.707 0 0 -0.707" type="box" size="1e-5 0.02 0.02" group="2" rgba="0 1 0 .1" />
            <site name="obj_rear"  pos="+0.075 0 0" quat="0 0 0 1"          type="box" size="1e-5 0.02 0.02" group="2" rgba="0 1 0 .1" />
        </body> -->

    </worldbody>

    <!-- Actuators -->
    <actuator>
        <!-- Original torque limits -->
<!--         <motor name="Shoulder_Link_motor" joint="Actuator1" gear="1 0 0 0 0 0" ctrlrange="0 0.8727" forcerange="-39 39"/>
        <motor name="HalfArm1_Link_motor" joint="Actuator2" gear="1 0 0 0 0 0" ctrlrange="0 0.8727" forcerange="-39 39"/>
        <motor name="HalfArm2_Link_motor" joint="Actuator3" gear="1 0 0 0 0 0" ctrlrange="0 0.8727" forcerange="-39 39"/>
        <motor name="ForeArm_Link_motor" joint="Actuator4" gear="1 0 0 0 0 0" ctrlrange="0 0.8727" forcerange="-39 39"/>
        <motor name="SphericalWrist1_Link_motor" joint="Actuator5" gear="1 0 0 0 0 0" ctrlrange="0 0.8727" forcerange="-9 9"/>
        <motor name="SphericalWrist2_Link_motor" joint="Actuator6" gear="1 0 0 0 0 0" ctrlrange="0 0.8727" forcerange="-9 9"/>
        <motor name="Bracelet_Link_motor" joint="Actuator7" gear="1 0 0 0 0 0" ctrlrange="0 0.8727" forcerange="-9 9"/> -->

        <motor name="Shoulder_Link_motor" joint="Actuator1" ctrlrange="-39 39" ctrllimited="true"/>
        <motor name="HalfArm1_Link_motor" joint="Actuator2" ctrlrange="-39 39" ctrllimited="true"/>
        <motor name="HalfArm2_Link_motor" joint="Actuator3" ctrlrange="-39 39" ctrllimited="true"/>
        <motor name="ForeArm_Link_motor" joint="Actuator4" ctrlrange="-39 39" ctrllimited="true"/>
        <motor name="SphericalWrist1_Link_motor" joint="Actuator5" ctrlrange="-9 9" ctrllimited="true"/>
        <motor name="SphericalWrist2_Link_motor" joint="Actuator6" ctrlrange="-9 9" ctrllimited="true"/>
        <motor name="Bracelet_Link_motor" joint="Actuator7" ctrlrange="-9 9" ctrllimited="true"/>
    </actuator>

    <!-- Key frames -->
    <keyframe>
        <!-- <key qpos='-1.78725 -2.2 0.0415694 0.56452 -0.856224 -0.0265256 0.251328'/> -->

        <!-- straight inside confined -->
        <!-- <key qpos='-1.76313 0.718148 0.412585 0.944309 -0.264092 -0.0633197 -0.162185'/> -->
        <!-- oblique inside confined -->
        <!-- <key qpos='0.345257 -1.0793 -1.78247 1.09897 2.30952 -0.0719616 -0.0482078'/>   -->
        <!-- lying outside pointing down  -->
        <!-- <key qpos='1.78725 -2.20122 0.0415694 -0.92376 -0.856224 -0.0265256 0.251328'/> -->
        <!-- <key qpos='-1.78725 2.20122 0.0415694 0.92376 -0.856224 -0.0265256 0.251328'/>         -->
        <!-- stop1st -->
        <!-- <key qpos='2.61664  0.706005 -0.343145   2.55786  0.267871  -1.20281   -2.7503'/> -->
        <!-- <key qpos='2.6  0.8 -0.4  2.8  0.2 -1.2 -2.8'/> -->
        <!-- stop2st -->        
        <!-- <key qpos='-0.565488 0.706005 -0.343145 2.55786 0.267871 -1.20281 -2.7503'/> -->
        <!-- <key qpos='0.062832 2.20122 0.0415694 0.92376 -0.856224 -0.0265256 0.251328'/> -->
        
        <!-- st left -->                
        <!-- <key qpos='-2.26981 0.758905 0.684271 0.955831 -0.449495 -0.0331292 -0.553772'/> -->
        <!-- st right -->                
        <!-- <key qpos='-1.31673 0.725238 0.403781 0.928758 -0.261151 -0.0558143 -0.130728'/> -->

        <!-- swing -->
        <!-- st -->
        <!-- <key qpos='0.797425 -1.85334 -1.97396 -0.760102 5.09595 0.0832437 -0.0305543'/> -->
        <!-- go -->
        <!-- <key qpos='3.15889 -1.75761 -1.54939 0.944074 4.54948 -0.107673 -0.129827'/> -->
        <!-- int -->
        <!-- <key qpos='2.07346 -1.66505 -1.97396 -1.97582 5.09595 0.0832437 -0.0305543'/> -->

        <!-- <key qpos='1.1786 -2.20079 -2.87931 -1.19375 5.1207 0.690514 0.923112'/> -->

        <!-- slide real test -->
        <!-- st -->
        <!-- <key qpos='0.0 -1.57 0 0 0 0 0'/> -->
        <!-- <key qpos='-0.5 1.6 0 -0.56452 0 0.492 -1.6'/> -->
        <!-- <key qpos='-0.019991 2.21439 0.000866731 -0.608677 -0.00021391 -0.0411999 -1.6'/> -->
        <!-- go -->
        <!-- <key qpos='-2.68628 -1.57 0 0 0 0 0'/> -->
        <!-- <key qpos='-2.68628 -2.20068 0.644537 0.670372 -0.509268 0.0758962 0.129557'/> -->
        <!-- <key qpos='0.8 2.21439 0.000870275 -0.608678 -0.000186858 -0.0405323 -1.6'/> -->

        <!-- test random -->
        <!-- <key qpos='0.0 -1.1 0 -0.56452 0 0.492 0'/> -->
        <!-- <key qpos='0.0 -2.20068 0.644451 0.670355 -0.509189 0.0760261 0.129331'/> -->
        <!-- <key qpos='-0.0662447 1.44 -0.210894 1.6679 -0.15708 -1.50797 -1.6'/> -->
    </keyframe>


    <!-- Contacts -->
<!--     <contact>
        <pair geom1="link6"  geom2="tplane" />
        <pair geom1="link7"  geom2="tplane" />
        <pair geom1="flange" geom2="tplane" />
        <pair geom1="link6"  geom2="object" friction=".6 .6" />
        <pair geom1="link7"  geom2="object" friction=".6 .6" />
        <pair geom1="flange" geom2="object" friction=".6 .6" />
        <pair geom1="tplane" geom2="object" friction="1.2 1.2" />
    </contact> -->

</mujoco>